2024-03-18 23:25:21.514 [info] WARNING:pygls.protocol:Cancel notification for unknown message id "3"

2024-03-18 23:25:21.516 [info] WARNING:pygls.protocol:Cancel notification for unknown message id "1"

2024-03-18 23:25:21.518 [info] WARNING:pygls.protocol:Cancel notification for unknown message id "2"

2024-03-18 23:25:33.103 [info] WARNING:pygls.protocol:Cancel notification for unknown message id "11"

2024-03-18 23:26:05.714 [info] WARNING:pygls.protocol:Cancel notification for unknown message id "27"

2024-03-18 23:28:41.498 [info] WARNING:pygls.protocol:Cancel notification for unknown message id "85"

2024-03-18 23:28:43.693 [info] WARNING:pygls.protocol:Cancel notification for unknown message id "90"

2024-03-18 23:28:46.527 [info] WARNING:pygls.protocol:Cancel notification for unknown message id "93"

2024-03-18 23:31:33.680 [info] ERROR:pygls.protocol:Failed to handle request 105 textDocument/hover HoverParams(text_document=TextDocumentIdentifier(uri='file:///workspace/info2602a2/App/app.py'), position=145:21, work_done_token=None)
Traceback (most recent call last):
  File "/workspace/.vscode-remote/extensions/ms-python.python-2024.2.1-universal/pythonFiles/lib/jedilsp/pygls/protocol.py", line 340, in _handle_request
    self._execute_request(msg_id, handler, params)
  File "/workspace/.vscode-remote/extensions/ms-python.python-2024.2.1-universal/pythonFiles/lib/jedilsp/pygls/protocol.py", line 264, in _execute_request
    self._send_response(msg_id, handler(params))
  File "/workspace/.vscode-remote/extensions/ms-python.python-2024.2.1-universal/pythonFiles/lib/jedilsp/jedi_language_server/server.py", line 384, in hover
    jedi_script.help(*jedi_lines),
  File "/workspace/.vscode-remote/extensions/ms-python.python-2024.2.1-universal/pythonFiles/lib/jedilsp/jedi/api/helpers.py", line 487, in wrapper
    return func(self, line, column, *args, **kwargs)
  File "/workspace/.vscode-remote/extensions/ms-python.python-2024.2.1-universal/pythonFiles/lib/jedilsp/jedi/api/__init__.py", line 372, in help
    definitions = self.goto(line, column, follow_imports=True)
  File "/workspace/.vscode-remote/extensions/ms-python.python-2024.2.1-universal/pythonFiles/lib/jedilsp/jedi/api/helpers.py", line 487, in wrapper
    return func(self, line, column, *args, **kwargs)
  File "/workspace/.vscode-remote/extensions/ms-python.python-2024.2.1-universal/pythonFiles/lib/jedilsp/jedi/api/__init__.py", line 300, in goto
    names = list(name.goto())
  File "/workspace/.vscode-remote/extensions/ms-python.python-2024.2.1-universal/pythonFiles/lib/jedilsp/jedi/inference/names.py", line 178, in goto
    i = trailer.parent.children.index(trailer)
ValueError: PythonNode(trailer, [<Operator: (>, PythonNode(arglist, [<String: '/login'>, <Operator: ,>, PythonNode(argument, [<Name: methods@146,21>, <Operator: =>, PythonNode(atom, [<Operator: [>, <String: 'POST'>, <Operator: ]>])])]), <Operator: )>]) is not in list

2024-03-18 23:31:33.682 [info] [Error - 11:31:33 PM] Request textDocument/hover failed.
2024-03-18 23:31:33.682 [info]   Message: ValueError: PythonNode(trailer, [<Operator: (>, PythonNode(arglist, [<String: '/login'>, <Operator: ,>, PythonNode(argument, [<Name: methods@146,21>, <Operator: =>, PythonNode(atom, [<Operator: [>, <String: 'POST'>, <Operator: ]>])])]), <Operator: )>]) is not in list
  Code: -32602 
{'traceback': ['  File "/workspace/.vscode-remote/extensions/ms-python.python-2024.2.1-universal/pythonFiles/lib/jedilsp/pygls/protocol.py", line 340, in _handle_request\n    self._execute_request(msg_id, handler, params)\n', '  File "/workspace/.vscode-remote/extensions/ms-python.python-2024.2.1-universal/pythonFiles/lib/jedilsp/pygls/protocol.py", line 264, in _execute_request\n    self._send_response(msg_id, handler(params))\n', '  File "/workspace/.vscode-remote/extensions/ms-python.python-2024.2.1-universal/pythonFiles/lib/jedilsp/jedi_language_server/server.py", line 384, in hover\n    jedi_script.help(*jedi_lines),\n', '  File "/workspace/.vscode-remote/extensions/ms-python.python-2024.2.1-universal/pythonFiles/lib/jedilsp/jedi/api/helpers.py", line 487, in wrapper\n    return func(self, line, column, *args, **kwargs)\n', '  File "/workspace/.vscode-remote/extensions/ms-python.python-2024.2.1-universal/pythonFiles/lib/jedilsp/jedi/api/__init__.py", line 372, in help\n    definitions = self.goto(line, column, follow_imports=True)\n', '  File "/workspace/.vscode-remote/extensions/ms-python.python-2024.2.1-universal/pythonFiles/lib/jedilsp/jedi/api/helpers.py", line 487, in wrapper\n    return func(self, line, column, *args, **kwargs)\n', '  File "/workspace/.vscode-remote/extensions/ms-python.python-2024.2.1-universal/pythonFiles/lib/jedilsp/jedi/api/__init__.py", line 300, in goto\n    names = list(name.goto())\n', '  File "/workspace/.vscode-remote/extensions/ms-python.python-2024.2.1-universal/pythonFiles/lib/jedilsp/jedi/inference/names.py", line 178, in goto\n    i = trailer.parent.children.index(trailer)\n']}
2024-03-18 23:32:25.046 [info] WARNING:pygls.protocol:Cancel notification for unknown message id "108"

